Î» python manage.py runserver
 ** On entry to DGEBAL parameter number  3 had an illegal value
 ** On entry to DGEHRD  parameter number  2 had an illegal value
 ** On entry to DORGHR DORGQR parameter number  2 had an illegal value
 ** On entry to DHSEQR parameter number  4 had an illegal value
 ** On entry to DGEBAL parameter number  3 had an illegal value
 ** On entry to DGEHRD  parameter number  2 had an illegal value
 ** On entry to DORGHR DORGQR parameter number  2 had an illegal value
 ** On entry to DHSEQR parameter number  4 had an illegal value
Watching for file changes with StatReloader
Exception in thread django-main-thread:
Traceback (most recent call last):
  File "C:\Program Files\WindowsApps\PythonSoftwareFoundation.Python.3.8_3.8.1776.0_x64__qbz5n2kfra8p0\lib\threading.py", line 932, in _bootstrap_inner
    self.run()
  File "C:\Program Files\WindowsApps\PythonSoftwareFoundation.Python.3.8_3.8.1776.0_x64__qbz5n2kfra8p0\lib\threading.py", line 870, in run
    self._target(*self._args, **self._kwargs)
  File "C:\Users\dillon\AppData\Local\Packages\PythonSoftwareFoundation.Python.3.8_qbz5n2kfra8p0\LocalCache\local-packages\Python38\site-packages\django\utils\autoreload.py", line 53, in wrapper
    fn(*args, **kwargs)
  File "C:\Users\dillon\AppData\Local\Packages\PythonSoftwareFoundation.Python.3.8_qbz5n2kfra8p0\LocalCache\local-packages\Python38\site-packages\django\core\management\commands\runserver.py", line 110, in inner_run
    autoreload.raise_last_exception()
  File "C:\Users\dillon\AppData\Local\Packages\PythonSoftwareFoundation.Python.3.8_qbz5n2kfra8p0\LocalCache\local-packages\Python38\site-packages\django\utils\autoreload.py", line 76, in raise_last_exception
    raise _exception[1]
  File "C:\Users\dillon\AppData\Local\Packages\PythonSoftwareFoundation.Python.3.8_qbz5n2kfra8p0\LocalCache\local-packages\Python38\site-packages\django\core\management\__init__.py", line 357, in execute
    autoreload.check_errors(django.setup)()
  File "C:\Users\dillon\AppData\Local\Packages\PythonSoftwareFoundation.Python.3.8_qbz5n2kfra8p0\LocalCache\local-packages\Python38\site-packages\django\utils\autoreload.py", line 53, in wrapper
    fn(*args, **kwargs)
  File "C:\Users\dillon\AppData\Local\Packages\PythonSoftwareFoundation.Python.3.8_qbz5n2kfra8p0\LocalCache\local-packages\Python38\site-packages\django\__init__.py", line 24, in setup
    apps.populate(settings.INSTALLED_APPS)
  File "C:\Users\dillon\AppData\Local\Packages\PythonSoftwareFoundation.Python.3.8_qbz5n2kfra8p0\LocalCache\local-packages\Python38\site-packages\django\apps\registry.py", line 114, in populate
    app_config.import_models()
  File "C:\Users\dillon\AppData\Local\Packages\PythonSoftwareFoundation.Python.3.8_qbz5n2kfra8p0\LocalCache\local-packages\Python38\site-packages\django\apps\config.py", line 211, in import_models
    self.models_module = import_module(models_module_name)
  File "C:\Program Files\WindowsApps\PythonSoftwareFoundation.Python.3.8_3.8.1776.0_x64__qbz5n2kfra8p0\lib\importlib\__init__.py", line 127, in import_module
    return _bootstrap._gcd_import(name[level:], package, level)
  File "<frozen importlib._bootstrap>", line 1014, in _gcd_import
  File "<frozen importlib._bootstrap>", line 991, in _find_and_load
  File "<frozen importlib._bootstrap>", line 975, in _find_and_load_unlocked
  File "<frozen importlib._bootstrap>", line 671, in _load_unlocked
  File "<frozen importlib._bootstrap_external>", line 783, in exec_module
  File "<frozen importlib._bootstrap>", line 219, in _call_with_frames_removed
  File "C:\Users\dillon\workspace\QIhubdjango\hub\models.py", line 6, in <module>
    import pandas
  File "C:\Users\dillon\AppData\Local\Packages\PythonSoftwareFoundation.Python.3.8_qbz5n2kfra8p0\LocalCache\local-packages\Python38\site-packages\pandas\__init__.py", line 11, in <module>
    __import__(dependency)
  File "C:\Users\dillon\AppData\Local\Packages\PythonSoftwareFoundation.Python.3.8_qbz5n2kfra8p0\LocalCache\local-packages\Python38\site-packages\numpy\__init__.py", line 305, in <module>
    _win_os_check()
  File "C:\Users\dillon\AppData\Local\Packages\PythonSoftwareFoundation.Python.3.8_qbz5n2kfra8p0\LocalCache\local-packages\Python38\site-packages\numpy\__init__.py", line 302, in _win_os_check
    raise RuntimeError(msg.format(__file__)) from None
RuntimeError: The current Numpy installation ('C:\\Users\\dillon\\AppData\\Local\\Packages\\PythonSoftwareFoundation.Python.3.8_qbz5n2kfra8p0\\LocalCache\\local-packages\\Python38\\site-packages\\numpy\\__init__.py') fails to pass a sanity check due to a bug in the windows runtime. See this issue for more information: https://tinyurl.com/y3dm3h86